Workbook

Sheet 1.Parking
A1: PARKING SPACES INVENTORY - PRODUCTION CITY
A2: Data extracted from plans: Basement 01 + Ground Floor (Gate Level)
A4: Level | B4: Standard spaces (incl. small 5000 length) | C4: Accessible / PRM spaces (1.20 m strip) | D4: TOTAL spaces | E4: Notes
A5: Basement 01 | B5: 204 | C5: 2 | D5: =SUM(B5:C5) -> 206
A6: Ground Floor (Gate Level) | B6: 156 | C6: 7 | D6: =SUM(B6:C6) -> 163
A7: PROJECT TOTAL | B7: =SUM(B5:B6) -> 360 | C7: =SUM(C5:C6) -> 9 | D7: =SUM(D5:D6) -> 369
A9: PERCENTAGE BREAKDOWN
A10: Type | B10: Spaces | C10: % of total
A11: Standard | B11: =B7 -> 360 | C11: =B11/$D$7 -> 0.97560976
A12: Accessible / PRM | B12: =C7 -> 9 | C12: =B12/$D$7 -> 0.024390244
A13: TOTAL | B13: =SUM(B11:B12) -> 369 | C13: =SUM(C11:C12) -> 1
A15: PARKING REQUIREMENT
A16: Category | B16: Units | C16: Spaces/unit | D16: Req. spaces | E16: Balance PRM
A17: Studio / 1BR / 2BR | B17: ='2.Program'!C99-SUM('2.Program'!C17,'2.Program'!C28,'2.Program'!C39,'2.Program'!C50,'2.Program'!C61,'2.Program'!C72,'2.Program'!C83,'2.Program'!C94) -> 338 | C17: 1 | D17: =B17*C17 -> 338
A18: 3BR | B18: =SUM('2.Program'!C17,'2.Program'!C28,'2.Program'!C39,'2.Program'!C50,'2.Program'!C61,'2.Program'!C72,'2.Program'!C83,'2.Program'!C94) -> 8 | C18: 2 | D18: =B18*C18 -> 16
A19: TOTAL REQUIRED | B19: =SUM(B17:B18) -> 346 | D19: =SUM(D17:D18) -> 354
A20: of which Accessible / PRM (2%) | B20: 0.02 | C20: Req. | D20: =ROUNDUP(D19*B20,0) -> 8 | E20: =C7-D20 -> 1
A21: BALANCE | D21: =D7-D19 -> 15 | E21: Available - Required

Sheet 2.Program
A1: BUILDING PROGRAM - PRODUCTION CITY
A4: 1. MAIN BUILDING USE
A5: Use | B5: RESIDENTIAL
A6: Dubai zone | B6: PRODUCTION CITY
A7: 2. RESIDENTIAL PROGRAM
A8: Floor | B8: Typology | C8: Units | D8: Int. area (m²). GFA | E8: Balcony (m²).Aprox | F8: Total Balcony (m²) | G8: Sellable/unit (m²) | H8: Total Sel.area (m²) | I8: Total GFA (m²)
A9: Floor 1 | B9: Studio Type A | C9: 23 | D9: =VLOOKUP(B9,$A$144:$D$156,2,FALSE) -> 31 | E9: =VLOOKUP(B9,$A$144:$D$156,3,FALSE) -> 8 | F9: =E9*C9 -> 184 | G9: =D9+E9 -> 39 | H9: =C9*G9 -> 897 | I9: =C9*D9 -> 713
B10: 1BR Type A | C10: 1 | D10: =VLOOKUP(B10,$A$144:$D$156,2,FALSE) -> 64.81 | E10: =VLOOKUP(B10,$A$144:$D$156,3,FALSE) -> 12 | F10: =E10*C10 -> 12 | G10: =D10+E10 -> 76.81 | H10: =C10*G10 -> 76.81 | I10: =C10*D10 -> 64.81
B11: 1BR Type B | C11: 12 | D11: =VLOOKUP(B11,$A$144:$D$156,2,FALSE) -> 61.75 | E11: =VLOOKUP(B11,$A$144:$D$156,3,FALSE) -> 12 | F11: =E11*C11 -> 144 | G11: =D11+E11 -> 73.75 | H11: =C11*G11 -> 885 | I11: =C11*D11 -> 741
B12: 1BR Type C | C12: 2 | D12: =VLOOKUP(B12,$A$144:$D$156,2,FALSE) -> 64.07 | E12: =VLOOKUP(B12,$A$144:$D$156,3,FALSE) -> 12 | F12: =E12*C12 -> 24 | G12: =D12+E12 -> 76.07 | H12: =C12*G12 -> 152.14 | I12: =C12*D12 -> 128.14
B13: 1BR Type D | C13: 1 | D13: =VLOOKUP(B13,$A$144:$D$156,2,FALSE) -> 63.74 | E13: =VLOOKUP(B13,$A$144:$D$156,3,FALSE) -> 12 | F13: =E13*C13 -> 12 | G13: =D13+E13 -> 75.74 | H13: =C13*G13 -> 75.74 | I13: =C13*D13 -> 63.74
B14: 2BR Type A | C14: 1 | D14: =VLOOKUP(B14,$A$144:$D$156,2,FALSE) -> 89.61 | E14: =VLOOKUP(B14,$A$144:$D$156,3,FALSE) -> 33 | F14: =E14*C14 -> 33 | G14: =D14+E14 -> 122.61 | H14: =C14*G14 -> 122.61 | I14: =C14*D14 -> 89.61
B15: 2BR Type B | C15: 2 | D15: =VLOOKUP(B15,$A$144:$D$156,2,FALSE) -> 86.09 | E15: =VLOOKUP(B15,$A$144:$D$156,3,FALSE) -> 33 | F15: =E15*C15 -> 66 | G15: =D15+E15 -> 119.09 | H15: =C15*G15 -> 238.18 | I15: =C15*D15 -> 172.18
B16: 2BR Type C | C16: 2 | D16: =VLOOKUP(B16,$A$144:$D$156,2,FALSE) -> 85.31 | E16: =VLOOKUP(B16,$A$144:$D$156,3,FALSE) -> 33 | F16: =E16*C16 -> 66 | G16: =D16+E16 -> 118.31 | H16: =C16*G16 -> 236.62 | I16: =C16*D16 -> 170.62
B17: 3BR Type A | C17: 1 | D17: =VLOOKUP(B17,$A$144:$D$156,2,FALSE) -> 133.4 | E17: =VLOOKUP(B17,$A$144:$D$156,3,FALSE) -> 33 | F17: =E17*C17 -> 33 | G17: =D17+E17 -> 166.4 | H17: =C17*G17 -> 166.4 | I17: =C17*D17 -> 133.4
A18: Subtotal Floor 1 | C18: =SUM(C9:C17) -> 45 | F18: =SUM(F9:F17) -> 574 | H18: =SUM(H9:H17) -> 2850.5 | I18: =SUM(I9:I17) -> 2276.5
A19: Floor 2 | B19: Studio Type A | C19: 23 | D19: =VLOOKUP(B19,$A$144:$D$156,2,FALSE) -> 31 | E19: =VLOOKUP(B19,$A$144:$D$156,3,FALSE) -> 8 | F19: =E19*C19 -> 184 | G19: =D19+E19 -> 39 | H19: =C19*G19 -> 897 | I19: =C19*D19 -> 713
B20: 1BR Type A | C20: 0 | D20: =VLOOKUP(B20,$A$144:$D$156,2,FALSE) -> 64.81 | E20: =VLOOKUP(B20,$A$144:$D$156,3,FALSE) -> 12 | F20: =E20*C20 -> 0 | G20: =D20+E20 -> 76.81 | H20: =C20*G20 -> 0 | I20: =C20*D20 -> 0
B21: 1BR Type B | C21: 12 | D21: =VLOOKUP(B21,$A$144:$D$156,2,FALSE) -> 61.75 | E21: =VLOOKUP(B21,$A$144:$D$156,3,FALSE) -> 12 | F21: =E21*C21 -> 144 | G21: =D21+E21 -> 73.75 | H21: =C21*G21 -> 885 | I21: =C21*D21 -> 741
B22: 1BR Type C | C22: 1 | D22: =VLOOKUP(B22,$A$144:$D$156,2,FALSE) -> 64.07 | E22: =VLOOKUP(B22,$A$144:$D$156,3,FALSE) -> 12 | F22: =E22*C22 -> 12 | G22: =D22+E22 -> 76.07 | H22: =C22*G22 -> 76.07 | I22: =C22*D22 -> 64.07
B23: 1BR Type D | C23: 1 | D23: =VLOOKUP(B23,$A$144:$D$156,2,FALSE) -> 63.74 | E23: =VLOOKUP(B23,$A$144:$D$156,3,FALSE) -> 12 | F23: =E23*C23 -> 12 | G23: =D23+E23 -> 75.74 | H23: =C23*G23 -> 75.74 | I23: =C23*D23 -> 63.74
B24: 2BR Type A | C24: 1 | D24: =VLOOKUP(B24,$A$144:$D$156,2,FALSE) -> 89.61 | E24: =VLOOKUP(B24,$A$144:$D$156,3,FALSE) -> 33 | F24: =E24*C24 -> 33 | G24: =D24+E24 -> 122.61 | H24: =C24*G24 -> 122.61 | I24: =C24*D24 -> 89.61
B25: 2BR Type B | C25: 2 | D25: =VLOOKUP(B25,$A$144:$D$156,2,FALSE) -> 86.09 | E25: =VLOOKUP(B25,$A$144:$D$156,3,FALSE) -> 33 | F25: =E25*C25 -> 66 | G25: =D25+E25 -> 119.09 | H25: =C25*G25 -> 238.18 | I25: =C25*D25 -> 172.18
B26: 2BR Type C | C26: 2 | D26: =VLOOKUP(B26,$A$144:$D$156,2,FALSE) -> 85.31 | E26: =VLOOKUP(B26,$A$144:$D$156,3,FALSE) -> 33 | F26: =E26*C26 -> 66 | G26: =D26+E26 -> 118.31 | H26: =C26*G26 -> 236.62 | I26: =C26*D26 -> 170.62
B27: 2BR Type D | C27: 2 | D27: =VLOOKUP(B27,$A$144:$D$156,2,FALSE) -> 73.76 | E27: =VLOOKUP(B27,$A$144:$D$156,3,FALSE) -> 33 | F27: =E27*C27 -> 66 | G27: =D27+E27 -> 106.76 | H27: =C27*G27 -> 213.52 | I27: =C27*D27 -> 147.52
B28: 3BR Type A | C28: 1 | D28: =VLOOKUP(B28,$A$144:$D$156,2,FALSE) -> 133.4 | E28: =VLOOKUP(B28,$A$144:$D$156,3,FALSE) -> 33 | F28: =E28*C28 -> 33 | G28: =D28+E28 -> 166.4 | H28: =C28*G28 -> 166.4 | I28: =C28*D28 -> 133.4
A29: Subtotal Floor 2 | C29: =SUM(C19:C28) -> 45 | F29: =SUM(F19:F28) -> 616 | H29: =SUM(H19:H28) -> 2911.14 | I29: =SUM(I19:I28) -> 2295.14
A30: Floor 3 | B30: Studio Type A | C30: 23 | D30: =VLOOKUP(B30,$A$144:$D$156,2,FALSE) -> 31 | E30: =VLOOKUP(B30,$A$144:$D$156,3,FALSE) -> 8 | F30: =E30*C30 -> 184 | G30: =D30+E30 -> 39 | H30: =C30*G30 -> 897 | I30: =C30*D30 -> 713
B31: 1BR Type A | C31: 0 | D31: =VLOOKUP(B31,$A$144:$D$156,2,FALSE) -> 64.81 | E31: =VLOOKUP(B31,$A$144:$D$156,3,FALSE) -> 12 | F31: =E31*C31 -> 0 | G31: =D31+E31 -> 76.81 | H31: =C31*G31 -> 0 | I31: =C31*D31 -> 0
B32: 1BR Type B | C32: 12 | D32: =VLOOKUP(B32,$A$144:$D$156,2,FALSE) -> 61.75 | E32: =VLOOKUP(B32,$A$144:$D$156,3,FALSE) -> 12 | F32: =E32*C32 -> 144 | G32: =D32+E32 -> 73.75 | H32: =C32*G32 -> 885 | I32: =C32*D32 -> 741
B33: 1BR Type C | C33: 1 | D33: =VLOOKUP(B33,$A$144:$D$156,2,FALSE) -> 64.07 | E33: =VLOOKUP(B33,$A$144:$D$156,3,FALSE) -> 12 | F33: =E33*C33 -> 12 | G33: =D33+E33 -> 76.07 | H33: =C33*G33 -> 76.07 | I33: =C33*D33 -> 64.07
B34: 1BR Type D | C34: 1 | D34: =VLOOKUP(B34,$A$144:$D$156,2,FALSE) -> 63.74 | E34: =VLOOKUP(B34,$A$144:$D$156,3,FALSE) -> 12 | F34: =E34*C34 -> 12 | G34: =D34+E34 -> 75.74 | H34: =C34*G34 -> 75.74 | I34: =C34*D34 -> 63.74
B35: 2BR Type A | C35: 1 | D35: =VLOOKUP(B35,$A$144:$D$156,2,FALSE) -> 89.61 | E35: =VLOOKUP(B35,$A$144:$D$156,3,FALSE) -> 33 | F35: =E35*C35 -> 33 | G35: =D35+E35 -> 122.61 | H35: =C35*G35 -> 122.61 | I35: =C35*D35 -> 89.61
B36: 2BR Type B | C36: 2 | D36: =VLOOKUP(B36,$A$144:$D$156,2,FALSE) -> 86.09 | E36: =VLOOKUP(B36,$A$144:$D$156,3,FALSE) -> 33 | F36: =E36*C36 -> 66 | G36: =D36+E36 -> 119.09 | H36: =C36*G36 -> 238.18 | I36: =C36*D36 -> 172.18
B37: 2BR Type C | C37: 2 | D37: =VLOOKUP(B37,$A$144:$D$156,2,FALSE) -> 85.31 | E37: =VLOOKUP(B37,$A$144:$D$156,3,FALSE) -> 33 | F37: =E37*C37 -> 66 | G37: =D37+E37 -> 118.31 | H37: =C37*G37 -> 236.62 | I37: =C37*D37 -> 170.62
B38: 2BR Type D | C38: 2 | D38: =VLOOKUP(B38,$A$144:$D$156,2,FALSE) -> 73.76 | E38: =VLOOKUP(B38,$A$144:$D$156,3,FALSE) -> 33 | F38: =E38*C38 -> 66 | G38: =D38+E38 -> 106.76 | H38: =C38*G38 -> 213.52 | I38: =C38*D38 -> 147.52
B39: 3BR Type A | C39: 1 | D39: =VLOOKUP(B39,$A$144:$D$156,2,FALSE) -> 133.4 | E39: =VLOOKUP(B39,$A$144:$D$156,3,FALSE) -> 33 | F39: =E39*C39 -> 33 | G39: =D39+E39 -> 166.4 | H39: =C39*G39 -> 166.4 | I39: =C39*D39 -> 133.4
A40: Subtotal Floor 3 | C40: =SUM(C30:C39) -> 45 | F40: =SUM(F30:F39) -> 616 | H40: =SUM(H30:H39) -> 2911.14 | I40: =SUM(I30:I39) -> 2295.14
A41: Floor 4 | B41: Studio Type A | C41: 23 | D41: =VLOOKUP(B41,$A$144:$D$156,2,FALSE) -> 31 | E41: =VLOOKUP(B41,$A$144:$D$156,3,FALSE) -> 8 | F41: =E41*C41 -> 184 | G41: =D41+E41 -> 39 | H41: =C41*G41 -> 897 | I41: =C41*D41 -> 713
B42: 1BR Type A | C42: 0 | D42: =VLOOKUP(B42,$A$144:$D$156,2,FALSE) -> 64.81 | E42: =VLOOKUP(B42,$A$144:$D$156,3,FALSE) -> 12 | F42: =E42*C42 -> 0 | G42: =D42+E42 -> 76.81 | H42: =C42*G42 -> 0 | I42: =C42*D42 -> 0
...

Sheet 3.Lifts 
A1: LIFT CALCULATION — PRODUCTION CITY. CIBSE Guide D
A3: STEP 1 — BUILDING POPULATION
A5: Occupancy assumptions
A6: Studio | B6: 1.5 | C6: pers / unit
A7: 1 BR | B7: 2 | C7: pers / unit
A8: 2 BR | B8: 3 | C8: pers / unit
A9: 3 BR + Maid | B9: 5 | C9: pers / unit
A11: Population by floor | B11: Studios | C11: 1 BR | D11: 2 BR | E11: 3 BR+M | F11: Total units | G11: Population
A12: Floor 1 | B12: ='2.Program'!C9 -> 23 | C12: =SUM('2.Program'!C10:C13) -> 16 | D12: =SUM('2.Program'!C14:C16) -> 5 | E12: ='2.Program'!C17 -> 1 | F12: =SUM(B12:E12) -> 45 | G12: =B12*$B$6+C12*$B$7+D12*$B$8+E12*$B$9 -> 86.5
A13: Floor 2 | B13: ='2.Program'!C19 -> 23 | C13: =SUM('2.Program'!C20:C23) -> 14 | D13: =SUM('2.Program'!C24:C27) -> 7 | E13: ='2.Program'!C28 -> 1 | F13: =SUM(B13:E13) -> 45 | G13: =B13*$B$6+C13*$B$7+D13*$B$8+E13*$B$9 -> 88.5
A14: Floor 3 | B14: ='2.Program'!C30 -> 23 | C14: =SUM('2.Program'!C31:C34) -> 14 | D14: =SUM('2.Program'!C35:C38) -> 7 | E14: ='2.Program'!C39 -> 1 | F14: =SUM(B14:E14) -> 45 | G14: =B14*$B$6+C14*$B$7+D14*$B$8+E14*$B$9 -> 88.5
A15: Floor 4 | B15: ='2.Program'!C41 -> 23 | C15: =SUM('2.Program'!C42:C45) -> 14 | D15: =SUM('2.Program'!C46:C49) -> 7 | E15: ='2.Program'!C50 -> 1 | F15: =SUM(B15:E15) -> 45 | G15: =B15*$B$6+C15*$B$7+D15*$B$8+E15*$B$9 -> 88.5
A16: Floor 5 | B16: ='2.Program'!C52 -> 23 | C16: =SUM('2.Program'!C53:C56) -> 14 | D16: =SUM('2.Program'!C57:C60) -> 7 | E16: ='2.Program'!C61 -> 1 | F16: =SUM(B16:E16) -> 45 | G16: =B16*$B$6+C16*$B$7+D16*$B$8+E16*$B$9 -> 88.5
A17: Floor 6 | B17: ='2.Program'!C63 -> 23 | C17: =SUM('2.Program'!C64:C67) -> 14 | D17: =SUM('2.Program'!C68:C71) -> 7 | E17: ='2.Program'!C72 -> 1 | F17: =SUM(B17:E17) -> 45 | G17: =B17*$B$6+C17*$B$7+D17*$B$8+E17*$B$9 -> 88.5
A18: Floor 7 | B18: ='2.Program'!C74 -> 22 | C18: =SUM('2.Program'!C75:C78) -> 14 | D18: =SUM('2.Program'!C79:C82) -> 7 | E18: ='2.Program'!C83 -> 1 | F18: =SUM(B18:E18) -> 44 | G18: =B18*$B$6+C18*$B$7+D18*$B$8+E18*$B$9 -> 87
A19: Floor 8 | B19: ='2.Program'!C85 -> 15 | C19: =SUM('2.Program'!C86:C89) -> 9 | D19: =SUM('2.Program'!C90:C93) -> 7 | E19: ='2.Program'!C94 -> 1 | F19: =SUM(B19:E19) -> 32 | G19: =B19*$B$6+C19*$B$7+D19*$B$8+E19*$B$9 -> 66.5
A20: TOTAL BUILDING | B20: =SUM(B12:B19) -> 175 | C20: =SUM(C12:C19) -> 109 | D20: =SUM(D12:D19) -> 54 | E20: =SUM(E12:E19) -> 8 | F20: =SUM(F12:F19) -> 346 | G20: =SUM(G12:G19) -> 682.5
A22: STEP 2 — HANDLING CAPACITY (CIBSE Guide D)
A24: Parameter | B24: Standard (5%) | C24: Premium (7%) | D24: Notes
A25: Total population | B25: =G20 -> 682.5 | C25: =G20 -> 682.5 | D25: From Step 1
A26: Handling capacity (%) | B26: 0.05 | C26: 0.07 | D26: % of population in 5 min
A27: Persons to move in 5 min | B27: =ROUNDUP(B25*B26,0) -> 35 | C27: =ROUNDUP(C25*C26,0) -> 48 | D27: Design demand
A29: STEP 3 — LIFT CABIN CAPACITY
A31: Cabin rated load (kg) | B31: Max persons | C31: @ 80% capacity
A32: 1000 | B32: =ROUNDDOWN(A32/75,0) -> 13 | C32: =ROUNDDOWN(B32*0.8,0) -> 10
A33: 1275 | B33: =ROUNDDOWN(A33/75,0) -> 17 | C33: =ROUNDDOWN(B33*0.8,0) -> 13
A34: 1600 | B34: =ROUNDDOWN(A34/75,0) -> 21 | C34: =ROUNDDOWN(B34*0.8,0) -> 16
A36: Selected cabin | B36: 1275 | C36: kg
A37: Persons per trip (80%) | B37: =ROUNDDOWN(ROUNDDOWN(B36/75,0)*0.8,0) -> 13 | C37: persons
A39: STEP 4 — ROUND TRIP TIME (RTT)
A41: Parameter | B41: Value | C41: Unit | D41: Notes
A42: Number of floors served | B42: 8 | C42: floors | D42: F1 to F8 (excl. ground)
A43: Floor-to-floor height | B43: 3.6 | C43: m | D43: Typical residential
A44: Total travel height (H) | B44: =B42*B43 -> 28.8 | C44: m | D44: Floors × height
A45: Lift speed (v) | B45: 1.75 | C45: m/s | D45: Typical residential Dubai
A46: Probable stops per trip | B46: =ROUND(SQRT(B42),1) -> 2.8 | C46: stops | D46: √N floors (approximation)
A47: Time per stop (door + load/unload) | B47: 8 | C47: s | D47: Open + board + close
A48: RTT (Round Trip Time) | B48: =ROUND(2*B44/B45+B46*B47,1) -> 55.3 | C48: s | D48: 2×H/v + stops×8s
A50: STEP 5 — CAPACITY PER LIFT (in 5 min)
A52: Parameter | B52: Value | C52: Unit | D52: Notes
...

Sheet 4.Garbage Room
A1: WASTE ROOM DIMENSIONING — PRODUCTION CITY
A3: DESIGN ASSUMPTIONS
A4: Parameter | B4: Value | C4: Unit | D4: Notes
A5: Waste generation rate | B5: 12 | C5: kg / 100 m² / day | D5: Dubai Municipality standard
A6: Storage capacity | B6: 2 | C6: days | D6: Minimum collection frequency
A7: Waste density (compacted) | B7: 150 | C7: kg / m³ | D7: Mixed residential waste
A8: Container capacity | B8: 2.5 | C8: m³ | D8: Standard waste container
A9: Container width | B9: 1.37 | C9: m
A10: Container length | B10: 2.04 | C10: m
A11: Separation between containers | B11: 0.15 | C11: m
A12: Front clearance | B12: 0.6 | C12: m | D12: Access / maneuvering space
A14: WASTE ROOM CALCULATION
A15: Parameter | B15: Value | C15: Unit | D15: Formula / Source
A16: Residential GFA (m²) | B16: ='2.Program'!I99 -> 17754.73 | C16: m² | D16: From Program sheet — Total Residential GFA
A17: Daily waste generation | B17: =ROUND(B16*B5/100,2) -> 2130.57 | C17: kg / day | D17: GFA × generation rate / 100
A18: Storage capacity (2 days) | B18: =ROUND(B17*B6,2) -> 4261.14 | C18: kg | D18: Daily generation × storage days
A19: Volume required | B19: =ROUND(B18/B7,2) -> 28.41 | C19: m³ | D19: Capacity / waste density
A20: N° containers (2.5 m³) | B20: =IF(B19=0,0,ROUNDUP(B19/B8,0)) -> 12 | C20: units | D20: Volume / container capacity (rounded up)
A21: Room width (containers side by side) | B21: =IF(B20=0,0,ROUND(B20*B9+(B20+1)*B11,2)) -> 18.39 | C21: m | D21: N° containers × width + separations
A22: Room depth | B22: =ROUND(B10+B12,2) -> 2.64 | C22: m | D22: Container length + front clearance
A24: TOTAL WASTE ROOM AREA | B24: =ROUND(B21*B22,2) -> 48.55 | C24: m² | D24: Room width × room depth

Sheet 4.Conclusions 
A1: PROJECT ANALYSIS - PRODUCTION CITY
A3: # | B3: Area | C3: Issue | D3: Impact
A4: 1 | B4: Basement Parking | C4: Travel distance exceeds 61 m max to evacuation staircase. Need to remove 4 parking spaces to comply with fire safety regulations. | D4: Loss of 4 spaces (369 → 365). Balance with required 354 reduces to +11 surplus.
A5: 2 | B5: Ground Floor Parking | C5: Open parking at ground floor level — vehicles are visible from the street. No facade screening or cladding in current design. | D5: Negative visual impact on building aesthetics and streetscape. May affect property values and community perception.
